Workbook

Sheet 2014 - 2015
B1: MARÇO 2014
E2: OC | F2: DATA | I2: PREÇO | J2: CODIGO | K2: DATA | L2: DATA | Q2: DATA | R2: VALOR DA
B3: CLIENTE | C3: PRODUTO | D3: PEDIDO | E3: DO | F3: DO | G3: QUANT | H3: UND | I3: POR | J3: DO | K3: DE | L3: DE | M3: N F | N3: QUANT | O3: SALDO | P3: VALOR | Q3: COMISSÃO | R3: COMISSÃO | S3: OBSERVAÇÃO | V3: AGC - BOM BLISTER | W3: VITOR (27) 99608-1521 ELIJOICE (27) 99754-4214 | AD3: ALTENIS (27) 99984-3055 | AH3: (27) 3371-3138 | AJ3: ERMERLANDO | AN3: MÊS | AO3: COMISSÃO | AP3: PAGAMENTO | AQ3: DATA | AR3: SALDO
E4: CLIENTE | F4: PEDIDO | I4: UND | J4: CLIENTE | K4: ENTREGA | L4: FATURA | Q4: 30 DD | R4: R$ | X4: OC | Y4: DATA | AB4: PREÇO | AC4: CODIGO | AD4: DATA | AE4: DATA | AJ4: DATA | AK4: VALOR DA | AN4: 41334 | AO4: 5402.32 | AP4: 5402.32 | AQ4: 06/06/2013 | AR4: =(AP4-AO4) -> 0
B5: DOCE MEL | C5: =IF(J5=1473,"BANDEJA PAPAYA PET - GF 15",IF(J5=0," ")) -> BANDEJA PAPAYA PET - GF 15 | D5: 12 | E5: 2666 | F5: 41600 | G5: 60.3 | H5: MIL | I5: 498 | J5: 1473 | K5: 41696 | L5: 41703 | M5: 2003 | N5: 60300 | O5: =(N5-G5*1000) -> 0 | P5: =(N5*I5/1000) -> 30029.4 | Q5: =(L5+30) -> 41733 | R5: =(P5*0.05) -> 1501.47 | V5: PRODUTO | W5: PEDIDO | X5: DO | Y5: DO | Z5: QUANT | AA5: UND | AB5: POR | AC5: DO | AD5: DE | AE5: DE | AF5: N F | AG5: QUANT | AH5: SALDO | AI5: VALOR | AJ5: COMISSÃO | AK5: COMISSÃO | AL5: OBSERVAÇÃO | AN5: 41365 | AO5: 6542.42 | AP5: 6542.42 | AQ5: 27/06/2013 | AR5: =(AP5-AO5) -> 0
B6: FRUT MEL | C6: BAND BLIS MAMÃO PAPAYA 4 UND | D6: 1 | E6: E-MAIL | F6: 41695 | G6: 15 | H6: MIL | I6: 470 | K6: 41688 | L6: 41712 | M6: 2010 | N6: 15200 | O6: =(N6-G6*1000) -> 200 | P6: =(N6*I6/1000) -> 7144 | Q6: =(L6+28) -> 41740 | R6: =(P6*0.05) -> 357.2 | S6: ITAU R$ 178,60 05/08/2014 | X6: CLIENTE | Y6: PEDIDO | AB6: UND | AC6: CLIENTE | AD6: ENTREGA | AE6: FATURA | AJ6: 35 DD | AK6: R$ | AN6: 41395 | AO6: 6284.78 | AP6: 4500 | AQ6: 01/08/2013 | AR6: =(AP6-AO6) -> -1784.78
B7: CALIMAN AGRICOLA | C7: BANDEJA TRANSP-04 CAV "OVO" | D7: 3 | E7: 005749/1 | F7: 41704 | G7: 25.2 | H7: MIL | I7: 470 | K7: 41717 | L7: 41710 | M7: 2008 | N7: 25200 | O7: =(N7-G7*1000) -> 0 | P7: =(N7*I7/1000) -> 11844 | Q7: =(L7+28) -> 41738 | R7: =(P7*0.05) -> 592.2 | AP7: 1784.78 | AQ7: 09/08/2013 | AR7: 0
B8: FRUTAS SOLO | C8: BANDEJA PAPAYA C/ 400 UND | D8: 1 | E8: 9140 | F8: 41709 | G8: 40 | H8: MIL | I8: 470 | J8: 8490 | K8: 41711 | L8: 41717 | M8: 2013 | N8: 40000 | O8: =(N8-G8*1000) -> 0 | P8: =(N8*I8/1000) -> 18800 | Q8: =(L8+35) -> 41752 | R8: =(P8*0.05) -> 940 | S8: ITAU R$ 470,00 05/08/2014 | V8: BANDEJAS MAMÃO PAPAYA 4 UND | W8: 1 | X8: e-mail | Y8: 41781 | Z8: 20 | AA8: MIL | AB8: 590 | AD8: 41800 | AE8: 41817 | AF8: 2083 | AG8: 21350 | AH8: =(AG8-Z8*1000) -> 1350 | AI8: =(AG8*AB8/1000) -> 12596.5 | AJ8: =(AE8+35) -> 41852 | AK8: =(AI8*0.05) -> 629.825 | AN8: 41426 | AO8: 6461.29 | AP8: 3461.29 | AQ8: 30/08/2013 | AR8: -3000
B9: DOCE MEL | C9: =IF(J9=1473,"BANDEJA PAPAYA PET - GF 15",IF(J9=0," ")) -> BANDEJA PAPAYA PET - GF 15 | D9: 13 | E9: 3133 | F9: 41712 | G9: 80 | H9: MIL | I9: 498 | J9: 1473 | K9: 41716 | L9: =(K9) -> 41716 | M9: 2016 | N9: 30000 | O9: =(N9-G9*1000) -> -50000 | P9: =(N9*I9/1000) -> 14940 | Q9: =(L9+30) -> 41746 | R9: =(P9*0.05) -> 747 | V9: BANDEJAS MAMÃO PAPAYA 4 UND | W9: 2 | X9: e-mail | Y9: 41893 | Z9: 40 | AA9: MIL | AB9: 570 | AD9: 41908 | AE9: 41913 | AF9: 2187 | AG9: 40000 | AH9: =(AG9-Z9*1000) -> 0 | AI9: =(AG9*AB9/1000) -> 22800 | AJ9: =(AE9+35) -> 41948 | AK9: =(AI9*0.05) -> 1140 | AP9: 3000 | AQ9: 41547 | AR9: 0
P10: =SUM(P5:P9) -> 82757.4 | R10: =SUM(R5:R9) -> 4137.87 | S10: PAGO | V10: BANDEJAS MAMÃO PAPAYA 4 UND | W10: 3 | X10: e-mail | Y10: 41914 | Z10: 40 | AA10: MIL | AB10: 570 | AD10: 41967 | AE10: 41969 | AF10: 2263 | AG10: 40000 | AH10: =(AG10-Z10*1000) -> 0 | AI10: =(AG10*AB10/1000) -> 22800 | AJ10: =(AE10+35) -> 42004 | AK10: =(AI10*0.05) -> 1140 | AN10: 41456 | AO10: 5559.2 | AP10: 2700 | AQ10: 17/10/2013 | AR10: -2859.2
AP11: 3500 | AQ11: 05/11/2013 | AR11: 640.8
B12: ABRIL 2014 | AN12: 41487 | AO12: 5249.16 | AP12: 640.8 | AQ12: 41583 | AR12: -4608.36
E13: OC | F13: DATA | I13: PREÇO | J13: CODIGO | K13: DATA | L13: DATA | Q13: DATA | R13: VALOR DA | AP13: 6000 | AQ13: 26/12/2013 | AR13: 1391.64
B14: CLIENTE | C14: PRODUTO | D14: PEDIDO | E14: DO | F14: DO | G14: QUANT | H14: UND | I14: POR | J14: DO | K14: DE | L14: DE | M14: N F | N14: QUANT | O14: SALDO | P14: VALOR | Q14: COMISSÃO | R14: COMISSÃO | S14: OBSERVAÇÃO | V14: AGC - VIDEPLAST | W14: VITOR (27) 99608-1521 ELIJOICE (27) 99754-4214 | AD14: somente mamão | AF14: (27) 3371-3138 | AH14: LIGAR JULHO | AN14: 41518 | AO14: 2876.79 | AP14: 1391.64 | AQ14: 26/12/2013 | AR14: -1485.15
E15: CLIENTE | F15: PEDIDO | I15: UND | J15: CLIENTE | K15: ENTREGA | L15: FATURA | Q15: 30 DD | R15: R$ | X15: OC | Y15: DATA | AB15: PREÇO | AC15: CODIGO | AD15: DATA | AE15: DATA | AJ15: DATA | AK15: VALOR DA | AP15: 2465.6 | AQ15: 21/02/2014 | AR15: 980.45
B16: DOCE MEL | C16: =IF(J16=1473,"BANDEJA PAPAYA PET - GF 15",IF(J16=0," ")) -> BANDEJA PAPAYA PET - GF 15 | D16: 13 | E16: 3133 | F16: 41712 | G16: 50 | H16: MIL | I16: 498 | J16: 1473 | K16: 41726 | L16: 41726 | M16: 2023 | N16: 50000 | O16: =(N16-G16*1000) -> 0 | P16: =(N16*I16/1000) -> 24900 | Q16: =(L16+30) -> 41756 | R16: =(P16*0.05) -> 1245 | V16: PRODUTO | W16: PEDIDO | X16: DO | Y16: DO | Z16: QUANT | AA16: UND | AB16: POR | AC16: DO | AD16: DE | AE16: DE | AF16: N F | AG16: QUANT | AH16: SALDO | AI16: VALOR | AJ16: COMISSÃO | AK16: COMISSÃO | AL16: OBSERVAÇÃO | AN16: 41548 | AO16: 2980.45 | AP16: 980.45 | AQ16: 41691 | AR16: -2000
B17: CALIMAN AGRICOLA | C17: BANDEJA TRANSP-04 CAV "OVO" | D17: 4 | E17: 005828/1 | F17: 41724 | G17: 25.2 | H17: MIL | I17: 470 | K17: 41726 | L17: =(K17) -> 41726 | M17: 2024 | N17: 25200 | O17: =(N17-G17*1000) -> 0 | P17: =(N17*I17/1000) -> 11844 | Q17: =(L17+28) -> 41754 | R17: =(P17*0.05) -> 592.2 | X17: CLIENTE | Y17: PEDIDO | AB17: UND | AC17: CLIENTE | AD17: ENTREGA | AE17: FATURA | AJ17: 35 DD | AK17: R$ | AP17: 2000 | AQ17: 07/03/2014 | AR17: 0
B18: DOCE MEL | C18: =IF(J18=1473,"BANDEJA PAPAYA PET - GF 15",IF(J18=0," ")) -> BANDEJA PAPAYA PET - GF 15 | D18: 14 | E18: 3134 | F18: 41712 | G18: 60 | H18: MIL | I18: 498 | J18: 1473 | K18: 41737 | L18: 41733 | M18: 2027 | N18: 60000 | O18: =(N18-G18*1000) -> 0 | P18: =(N18*I18/1000) -> 29880 | Q18: =(L18+30) -> 41763 | R18: =(P18*0.05) -> 1494 | AN18: 41579 | AO18: 0 | AP18: 0 | AR18: 0
B19: CALIMAN AGRICOLA | C19: BANDEJA TRANSP-04 CAV "OVO" | D19: 5 | E19: 005828/1 | F19: 41724 | G19: 25.2 | H19: MIL | I19: 470 | K19: 41733 | L19: 41740 | M19: 2031 | N19: 25200 | O19: =(N19-G19*1000) -> 0 | P19: =(N19*I19/1000) -> 11844 | Q19: =(L19+28) -> 41768 | R19: =(P19*0.05) -> 592.2 | V19: BANDEJAS MAMÃO PAPAYA 4 UND | W19: 1 | X19: e-mail | Y19: 41781 | Z19: 20 | AA19: MIL | AB19: 590 | AD19: 41800 | AE19: 41817 | AF19: 2083 | AG19: 21350 | AH19: =(AG19-Z19*1000) -> 1350 | AI19: =(AG19*AB19/1000) -> 12596.5 | AJ19: =(AE19+35) -> 41852 | AK19: =(AI19*0.05) -> 629.825 | AN19: 41609 | AO19: 2701.45 | AP19: 2701.45 | AQ19: 03/04/2014 | AR19: 0
B20: CASA SUIÇA | C20: BANDEJA RETANGULAR - JANDIRA | D20: 226 | E20: E-MAIL | F20: 41723 | G20: 100 | H20: MIL | I20: 60 | J20: 9124 | K20: 41745 | L20: 41745 | M20: 2036 | N20: 102000 | O20: =(N20-G20*1000) -> 2000 | P20: =(N20*I20/1000) -> 6120 | Q20: =(L20+35) -> 41780 | R20: =(P20*0.05) -> 306 | V20: BANDEJAS MAMÃO PAPAYA 4 UND | W20: 2 | X20: e-mail | Y20: 41893 | Z20: 40 | AA20: MIL | AB20: 570 | AD20: 41908 | AE20: 41913 | AF20: 2187 | AG20: 40000 | AH20: =(AG20-Z20*1000) -> 0 | AI20: =(AG20*AB20/1000) -> 22800 | AJ20: =(AE20+35) -> 41948 | AK20: =(AI20*0.05) -> 1140 | AN20: 41640 | AO20: 2689.47 | AP20: 2689.47 | AQ20: 41754 | AR20: 0
P21: =SUM(P16:P20) -> 84588 | R21: =(P21*0.05) -> 4229.4 | S21: PAGO | V21: BANDEJAS MAMÃO PAPAYA 4 UND | W21: 3 | X21: e-mail | Y21: 41914 | Z21: 40 | AA21: MIL | AB21: 570 | AD21: 41967 | AE21: 41969 | AF21: 2263 | AG21: 40000 | AH21: =(AG21-Z21*1000) -> 0 | AI21: =(AG21*AB21/1000) -> 22800 | AJ21: =(AE21+35) -> 42004 | AK21: =(AI21*0.05) -> 1140 | AN21: 41671 | AO21: 1738.8 | AP21: 1738.8 | AQ21: 08/05/2014 | AR21: 0
AN22: 41699 | AO22: 4137.87 | AP22: 2137.87 | AQ22: 23/05/2014 | AR22: -2000
B23: MAIO 2014 | AP23: 2000 | AQ23: 20/06/2014 | AR23: 0
E24: OC | F24: DATA | I24: PREÇO | J24: CODIGO | K24: DATA | L24: DATA | Q24: DATA | R24: VALOR DA | AN24: 41730 | AO24: 4229.4 | AP24: 2000 | AQ24: 41834 | AR24: -2229.4
B25: CLIENTE | C25: PRODUTO | D25: PEDIDO | E25: DO | F25: DO | G25: QUANT | H25: UND | I25: POR | J25: DO | K25: DE | L25: DE | M25: N F | N25: QUANT | O25: SALDO | P25: VALOR | Q25: COMISSÃO | R25: COMISSÃO | S25: OBSERVAÇÃO | AP25: 2229.4 | AQ25: 18/07/2014 | AR25: 0
E26: CLIENTE | F26: PEDIDO | I26: UND | J26: CLIENTE | K26: ENTREGA | L26: FATURA | Q26: 30 DD | R26: R$ | V26: AGRICOLA Q.DELICIA | W26: URBANO (81) 99946-3622 | Z26: (81) 3252-1132 | AC26: DA PAZ | AD26: CARINE | AE26: UVA MAMÃO | AG26: RENATA | AH26: ligar amanhã | AN26: 41760 | AO26: 3332.1 | AP26: 2000 | AQ26: 41859 | AR26: =(AP26-AO26) -> -1332.1
B27: CALIMAN AGRICOLA | C27: BANDEJA TRANSP-04 CAV "OVO" | D27: 6 | E27: 005828/1 | F27: 41724 | G27: 25.2 | H27: MIL | I27: 470 | K27: 41743 | L27: 41752 | M27: 2040 | N27: 25200 | O27: =(N27-G27*1000) -> 0 | P27: =(N27*I27/1000) -> 11844 | Q27: =(L27+28) -> 41780 | R27: =(P27*0.05) -> 592.2 | X27: OC | Y27: DATA | AB27: PREÇO | AC27: CODIGO | AD27: DATA | AE27: DATA | AJ27: DATA | AK27: VALOR DA | AP27: 1332.1 | AQ27: 27/08/2014 | AR27: 0
B28: FRUT MEL | C28: BAND BLIS MAMÃO PAPAYA 4 UND | D28: 2 | E28: E-MAIL | F28: 41737 | G28: 15 | H28: MIL | I28: 470 | K28: 41745 | L28: 41754 | M28: 2045 | N28: 15200 | O28: =(N28-G28*1000) -> 200 | P28: =(N28*I28/1000) -> 7144 | Q28: =(L28+28) -> 41782 | R28: =(P28*0.05) -> 357.2 | S28: BB R$ 178,60 08/08/2014 | V28: PRODUTO | W28: PEDIDO | X28: DO | Y28: DO | Z28: QUANT | AA28: UND | AB28: POR | AC28: DO | AD28: DE | AE28: DE | AF28: N F | AG28: QUANT | AH28: SALDO | AI28: VALOR | AJ28: COMISSÃO | AK28: COMISSÃO | AL28: OBSERVAÇÃO | AN28: 41791 | AO28: 4538.6 | AP28: 2000 | AQ28: 04/09/2014 | AR28: =(AP28-AO28) -> -2538.6
B29: CASA SUIÇA | C29: BANDEJA RETANGULAR - JANDIRA | D29: 227 | E29: E-MAIL | F29: 41723 | G29: 100 | H29: MIL | I29: 60 | J29: 9124 | K29: 41759 | L29: 41754 | M29: 2044 | N29: 99000 | O29: =(N29-G29*1000) -> -1000 | P29: =(N29*I29/1000) -> 5940 | Q29: =(L29+35) -> 41789 | R29: =(P29*0.05) -> 297 | X29: CLIENTE | Y29: PEDIDO | AB29: UND | AC29: CLIENTE | AD29: ENTREGA | AE29: FATURA | AJ29: 35 DD | AK29: R$ | AP29: 2358.6 | AQ29: 18/09/2014 | AR29: =(AP29+AR28) -> -180
B30: FRUTAS SOLO | C30: BANDEJA PAPAYA C/ 400 UND | D30: 2 | E30: 9724 | F30: 41754 | G30: 40 | H30: MIL | I30: 470 | J30: 8490 | K30: 41754 | L30: 41772 | M30: 2053 | N30: 40000 | O30: =(N30-G30*1000) -> 0 | P30: =(N30*I30/1000) -> 18800 | Q30: =(L30+35) -> 41807 | R30: =(P30*0.05) -> 940 | S30: BB R$ 470,00 08/08/2014 | AP30: 3000 | AQ30: 41927 | AR30: =(AP30+AR29) -> 2820
B31: CALIMAN AGRICOLA | C31: BANDEJA TRANSP-04 CAV "OVO" | D31: 9 | E31: 005828/1 | F31: 41724 | G31: 25.2 | H31: MIL | I31: 470 | K31: 41771 | L31: 41772 | M31: 2054 | N31: 25200 | O31: =(N31-G31*1000) -> 0 | P31: =(N31*I31/1000) -> 11844 | Q31: =(L31+35) -> 41807 | R31: =(P31*0.05) -> 592.2 | V31: BANDEJAS MAMÃO PAPAYA 4 UND | W31: 1 | X31: E-MAIL | Y31: 41824 | Z31: 10 | AA31: MIL | AB31: 470 | AD31: 41827 | AE31: 41827 | AF31: 2092 | AG31: 10000 | AH31: =(AG31-Z31*1000) -> 0 | AI31: =(AG31*AB31/1000) -> 4700 | AJ31: =(AE31+35) -> 41862 | AK31: =(AI31*0.05) -> 235 | AN31: 41821 | AO31: 4997.93 | AP31: 2820 | AQ31: 15/10/2014 | AR31: =(AP31-AO31) -> -2177.93
B32: CASA SUIÇA | C32: BANDEJA RETANGULAR - JANDIRA | D32: 228 | E32: E-MAIL | F32: 41723 | G32: 100 | H32: MIL | I32: 60 | J32: 9124 | K32: 41773 | L32: 41775 | M32: 2056 | N32: 102000 | O32: =(N32-G32*1000) -> 2000 | P32: =(N32*I32/1000) -> 6120 | Q32: =(L32+35) -> 41810 | R32: =(P32*0.05) -> 306 | S32: 21/05 20/06 | V32: BANDEJAS MAMÃO PAPAYA 4 UND | W32: 2 | X32: E-MAIL | Y32: 41971 | Z32: 5 | AA32: MIL | AB32: 470 | AD32: 41976 | AE32: 41977 | AF32: 2270 | AG32: 5200 | AH32: =(AG32-Z32*1000) -> 200 | AI32: =(AG32*AB32/1000) -> 2444 | AJ32: =(AE32+35) -> 42012 | AK32: =(AI32*0.05) -> 122.2 | AP32: 4044.9 | AQ32: 30/10/2014 | AR32: =(AP32+AR31) -> 1866.97
B33: CASA SUIÇA | C33: BERÇO AMANTEIGADOS | D33: 225 | E33: E-MAIL | F33: 41723 | G33: 25 | H33: MIL | I33: 198 | J33: 13822 | K33: 41773 | L33: 41761 | M33: 2049 | N33: 1000 | O33: =(N33-G33*1000) -> -24000 | P33: =(N33*I33/1000) -> 198 | Q33: =(L33+35) -> 41796 | R33: =(P33*0.05) -> 9.9 | V33: BANDEJAS MAMÃO PAPAYA 2 UND | W33: 3 | X33: E-MAIL | Y33: 41971 | Z33: 10 | AA33: MIL | AB33: 280 | AD33: 41976 | AE33: 41977 | AF33: 2270 | AG33: 10400 | AH33: =(AG33-Z33*1000) -> 400 | AI33: =(AG33*AB33/1000) -> 2912 | AJ33: =(AE33+35) -> 42012 | AK33: =(AI33*0.05) -> 145.6 | AN33: 41852 | AO33: 2584.4 | AP33: 2584.4 | AQ33: 03/10/2014 | AR33: =(AP33-AO33) -> 0
B34: CASA SUIÇA | C34: BERÇO AMANTEIGADOS | D34: 225 | E34: E-MAIL | F34: 41723 | G34: 24 | H34: MIL | I34: 198 | J34: 13822 | K34: 41773 | L34: 41775 | M34: 2056 | N34: 24000 | O34: =(N34-G34*1000) -> 0 | P34: =(N34*I34/1000) -> 4752 | Q34: =(L34+35) -> 41810 | R34: =(P34*0.05) -> 237.6 | V34: BANDEJAS MAMÃO PAPAYA 4 UND | W34: 4 | X34: E-MAIL | Y34: 42059 | Z34: 5 | AA34: MIL | AB34: 470 | AD34: 42061 | AE34: 42061 | AF34: 2358 | AG34: 5000 | AH34: =(AG34-Z34*1000) -> 0 | AI34: =(AG34*AB34/1000) -> 2350 | AJ34: =(AE34+35) -> 42096 | AK34: =(AI34*0.05) -> 117.5 | AN34: 41883 | AO34: 5896.64 | AP34: 1866.97 | AQ34: 30/10/2014 | AR34: =(AP34-AO34) -> -4029.67
P35: =SUM(P27:P34) -> 66642 | R35: =(P35*0.05) -> 3332.1 | S35: PAGO | V35: BANDEJAS MAMÃO PAPAYA 2 UND | W35: 5 | X35: E-MAIL | Y35: 42059 | Z35: 10 | AA35: MIL | AB35: 280 | AD35: 42061 | AE35: 42061 | AF35: 2358 | AG35: 10000 | AH35: =(AG35-Z35*1000) -> 0 | AI35: =(AG35*AB35/1000) -> 2800 | AJ35: =(AE35+35) -> 42096 | AK35: =(AI35*0.05) -> 140 | AP35: 3896.64 | AQ35: 18/11/2014 | AR35: =(AP35+AR34) -> -133.03
V36: BANDEJAS MAMÃO PAPAYA 2 UND | W36: 6 | X36: E-MAIL | Y36: 42173 | Z36: 3 | AA36: MIL | AB36: 280 | AD36: 42174 | AE36: 42179 | AF36: 2485 | AG36: 3000 | AH36: =(AG36-Z36*1000) -> 0 | AI36: =(AG36*AB36/1000) -> 840 | AJ36: =(AE36+35) -> 42214 | AK36: =(AI36*0.05) -> 42 | AP36: 2000 | AQ36: 41976 | AR36: =(AP36+AR35) -> 1866.97
B37: JUNHO 2014 | V37: BANDEJAS MAMÃO PAPAYA 4 UND | W37: 7 | X37: E-MAIL | Y37: 42173 | Z37: 3 | AA37: MIL | AB37: 470 | AD37: 42174 | AE37: 42179 | AF37: 2485 | AG37: 3200 | AH37: =(AG37-Z37*1000) -> 200 | AI37: =(AG37*AB37/1000) -> 1504 | AJ37: =(AE37+35) -> 42214 | AK37: =(AI37*0.05) -> 75.2 | AN37: 41913 | AO37: 9827.6 | AP37: 1866.97 | AQ37: 41976 | AR37: =(AP37-AO37) -> -7960.63
E38: OC | F38: DATA | I38: PREÇO | J38: CODIGO | K38: DATA | L38: DATA | Q38: DATA | R38: VALOR DA | V38: CUMBUCA 500G | W38: 8 | X38: E-MAIL | Y38: 42173 | Z38: 10 | AA38: MIL | AB38: 300 | AD38: 42174 | AE38: 42179 | AF38: 2485 | AG38: 10000 | AH38: =(AG38-Z38*1000) -> 0 | AI38: =(AG38*AB38/1000) -> 3000 | AJ38: =(AE38+35) -> 42214 | AK38: =(AI38*0.05) -> 150 | AP38: 3000 | AQ38: 12/12/2014 | AR38: =(AP38+AR37) -> -4960.63
B39: CLIENTE | C39: PRODUTO | D39: PEDIDO | E39: DO | F39: DO | G39: QUANT | H39: UND | I39: POR | J39: DO | K39: DE | L39: DE | M39: N F | N39: QUANT | O39: SALDO | P39: VALOR | Q39: COMISSÃO | R39: COMISSÃO | S39: OBSERVAÇÃO | V39: CUMBUCA 500G | W39: 10 | X39: E-MAIL | Y39: 42214 | Z39: 10 | AA39: MIL | AB39: 300 | AD39: 42215 | AE39: 42215 | AF39: 2520 | AG39: 10000 | AH39: =(AG39-Z39*1000) -> 0 | AI39: =(AG39*AB39/1000) -> 3000 | AJ39: =(AE39+35) -> 42250 | AK39: =(AI39*0.05) -> 150 | AP39: 2500 | AQ39: 05/01/2015 | AR39: =(AP39+AR38) -> -2460.63
E40: CLIENTE | F40: PEDIDO | I40: UND | J40: CLIENTE | K40: ENTREGA | L40: FATURA | Q40: 30 DD | R40: R$ | V40: BANDEJAS MAMÃO PAPAYA 4 UND | W40: 11 | X40: E-MAIL | Y40: 42173 | Z40: 3 | AA40: MIL | AB40: 470 | AD40: 42215 | AE40: 42215 | AF40: 2520 | AG40: 3200 | AH40: =(AG40-Z40*1000) -> 200 | AI40: =(AG40*AB40/1000) -> 1504 | AJ40: =(AE40+35) -> 42250 | AK40: =(AI40*0.05) -> 75.2 | AP40: 2327.6 | AQ40: 05/01/2015 | AR40: =(AP40+AR39) -> -133.03
...

Sheet 2017
B3: JANEIRO 2016 | Y3: ermerlando 27 997544214 | AC3: ALTENIS (27) 99984-3055 | AF3: JUNIOR
E4: OC | F4: DATA | I4: PREÇO | J4: CODIGO | K4: DATA | L4: DATA | Q4: DATA | R4: VALOR DA | V4: AGC | W4: VITOR (27) 99608-1521 ELIJOICE (27) 99713-8956 | AD4: somente mamão | AF4: (27) 3371-3138 | AH4: 27 99754-4214 JUNIOR/JOÃO PAULO | AN4: MÊS | AO4: COMISSÃO | AP4: PAGAMENTO | AQ4: DATA | AR4: SALDO
B5: CLIENTE | C5: PRODUTO | D5: PEDIDO | E5: DO | F5: DO | G5: QUANT | H5: UND | I5: POR | J5: DO | K5: DE | L5: DE | M5: N F | N5: QUANT | O5: SALDO | P5: VALOR | Q5: COMISSÃO | R5: COMISSÃO | S5: OBSERVAÇÃO | X5: OC | Y5: DATA | AB5: PREÇO | AC5: CODIGO | AD5: DATA | AE5: DATA | AJ5: DATA | AK5: VALOR DA | AN5: 41334 | AO5: 5402.32 | AP5: 5402.32 | AQ5: 06/06/2013 | AR5: =(AP5-AO5) -> 0
E6: CLIENTE | F6: PEDIDO | I6: UND | J6: CLIENTE | K6: ENTREGA | L6: FATURA | Q6: 30 DD | R6: R$ | V6: PRODUTO | W6: PEDIDO | X6: DO | Y6: DO | Z6: QUANT | AA6: UND | AB6: POR | AC6: DO | AD6: DE | AE6: DE | AF6: N F | AG6: QUANT | AH6: SALDO | AI6: VALOR | AJ6: COMISSÃO | AK6: COMISSÃO | AL6: OBSERVAÇÃO | AN6: 41365 | AO6: 6542.42 | AP6: 6542.42 | AQ6: 27/06/2013 | AR6: =(AP6-AO6) -> 0
B7: DOCE MEL | C7: =IF(J7=1473,"BANDEJA PAPAYA PET - GF 15",IF(J7=0," ")) -> BANDEJA PAPAYA PET - GF 15 | D7: 29 | E7: 20387 | F7: 42332 | G7: 50 | H7: MIL | I7: 449.5 | J7: 1473 | K7: 42335 | L7: 42339 | M7: 2618 | N7: 50000 | O7: =(N7-G7*1000) -> 0 | P7: =(N7*I7/1000) -> 22475 | Q7: =(L7+30) -> 42369 | R7: =(P7*0.05) -> 1123.75 | X7: CLIENTE | Y7: PEDIDO | AB7: UND | AC7: CLIENTE | AD7: ENTREGA | AE7: FATURA | AJ7: 35 DD | AK7: R$ | AN7: 41395 | AO7: 6284.78 | AP7: 4500 | AQ7: 01/08/2013 | AR7: =(AP7-AO7) -> -1784.78
B8: DOCE MEL | C8: =IF(J8=1473,"BANDEJA PAPAYA PET - GF 15",IF(J8=0," ")) -> BANDEJA PAPAYA PET - GF 15 | D8: 30 | E8: 20387 | F8: 42332 | G8: 40 | H8: MIL | I8: 449.5 | J8: 1473 | K8: 42365 | L8: 42359 | M8: 2637 | N8: 40000 | O8: =(N8-G8*1000) -> 0 | P8: =(N8*I8/1000) -> 17980 | Q8: =(L8+30) -> 42389 | R8: =(P8*0.05) -> 899 | AP8: 1784.78 | AQ8: 09/08/2013 | AR8: 0
B9: FRUTAS SOLO | C9: BANDEJA PAPAYA C/ 400 UND | D9: 12 | E9: e-mail | F9: 42337 | G9: 40 | H9: MIL | I9: 449.5 | J9: 8490 | K9: 42341 | L9: 42348 | M9: 2627 | N9: 40000 | O9: =(N9-G9*1000) -> 0 | P9: =(N9*I9/1000) -> 17980 | Q9: =(L9+35) -> 42383 | R9: =(P9*0.05) -> 899 | AN9: 41426 | AO9: 6461.29 | AP9: 3461.29 | AQ9: 30/08/2013 | AR9: -3000
B10: BELLO FRUIT | C10: BANDEJA CLAIM SHELL PAPAYA 4 UND | D10: 7 | E10: SKIPE | F10: 42338 | G10: 20 | H10: MIL | I10: 449.5 | K10: 42346 | L10: 42342 | M10: 2623 | N10: 20000 | O10: =(N10-G10*1000) -> 0 | P10: =(N10*I10/1000) -> 8990 | Q10: =(L10+35) -> 42377 | R10: =(P10*0.05) -> 449.5 | AP10: 3000 | AQ10: 41547 | AR10: 0
B11: Q'DELICIA | C11: BANDEJAS MAMÃO PAPAYA 4 UND | D11: 18 | E11: E-MAIL | F11: 42342 | G11: 3 | H11: MIL | I11: 449.5 | K11: 42346 | L11: 42347 | M11: 2626 | N11: 3200 | O11: =(N11-G11*1000) -> 200 | P11: =(N11*I11/1000) -> 1438.4 | Q11: =(L11+35) -> 42382 | R11: =(P11*0.05) -> 71.92 | AN11: 41456 | AO11: 5559.2 | AP11: 2700 | AQ11: 17/10/2013 | AR11: -2859.2
B12: Q'DELICIA | C12: CUMBUCA 500 G 35 | D12: 19 | E12: E-MAIL | F12: 42342 | G12: 5 | H12: MIL | I12: 300 | K12: 42346 | L12: 42347 | M12: 2626 | N12: 5000 | O12: =(N12-G12*1000) -> 0 | P12: =(N12*I12/1000) -> 1500 | Q12: =(L12+35) -> 42382 | R12: =(P12*0.05) -> 75 | AP12: 3500 | AQ12: 05/11/2013 | AR12: 640.8
B13: Q'DELICIA | C13: BANDEJAS MAMÃO PAPAYA 2 UND | D13: 20 | E13: E-MAIL | F13: 42342 | G13: 5 | H13: MIL | I13: 320 | K13: 42346 | L13: 42347 | M13: 2626 | N13: 5600 | O13: =(N13-G13*1000) -> 600 | P13: =(N13*I13/1000) -> 1792 | Q13: =(L13+35) -> 42382 | R13: =(P13*0.05) -> 89.6 | AN13: 41487 | AO13: 5249.16 | AP13: 640.8 | AQ13: 41583 | AR13: -4608.36
B14: DE MARCHI | C14: CUMBUCA 500 - G 35 | D14: 1 | E14: VERBAL | F14: 42348 | G14: 10 | H14: MIL | I14: 300 | K14: 42353 | L14: 42353 | M14: 2632 | N14: 10350 | O14: =(N14-G14*1000) -> 350 | P14: =(N14*I14/1000) -> 3105 | Q14: =(L14+30) -> 42383 | R14: =(P14*0.05) -> 155.25 | AP14: 6000 | AQ14: 26/12/2013 | AR14: 1391.64
B15: NORTE FRUIT | C15: BANDEJA PAPAYA PET 2 UND | D15: 44 | E15: e-mail | F15: 42332 | G15: 10 | H15: MIL | I15: 300 | K15: 42335 | L15: 42349 | M15: 2628 | N15: 10000 | O15: =(N15-G15*1000) -> 0 | P15: =(N15*I15/1000) -> 3000 | Q15: =(L15+28) -> 42377 | R15: =(P15*0.05) -> 150 | V15: AGRICOLA Q.DELICIA - SERRAPLAST | W15: URBANO (81) 99946-3622 | Z15: (81) 3252-1132 | AC15: DA PAZ | AD15: CARINE | AE15: UVA MAMÃO | AG15: RENATA | AN15: 41518 | AO15: 2876.79 | AP15: 1391.64 | AQ15: 26/12/2013 | AR15: -1485.15
B16: NORTE FRUIT | C16: BANDEJA PAPAYA PET 4 UND | D16: 45 | E16: e-mail | F16: 42332 | G16: 10 | H16: MIL | I16: 449.5 | K16: 42335 | L16: 42349 | M16: 2628 | N16: 10000 | O16: =(N16-G16*1000) -> 0 | P16: =(N16*I16/1000) -> 4495 | Q16: =(L16+28) -> 42377 | R16: =(P16*0.05) -> 224.75 | X16: OC | Y16: DATA | AB16: PREÇO | AC16: CODIGO | AD16: DATA | AE16: DATA | AJ16: DATA | AK16: VALOR DA | AP16: 2465.6 | AQ16: 21/02/2014 | AR16: 980.45
B17: CASA DA UVA | C17: CUMBUCA 500 - G 35 | D17: 5 | E17: E-MAIL | F17: 42342 | G17: 12 | H17: MIL | I17: 300 | K17: 42346 | L17: 42349 | M17: 2629 | N17: 12000 | O17: =(N17-G17*1000) -> 0 | P17: =(N17*I17/1000) -> 3600 | Q17: =(L17+35) -> 42384 | R17: =(P17*0.05) -> 180 | V17: PRODUTO | W17: PEDIDO | X17: DO | Y17: DO | Z17: QUANT | AA17: UND | AB17: POR | AC17: DO | AD17: DE | AE17: DE | AF17: N F | AG17: QUANT | AH17: SALDO | AI17: VALOR | AJ17: COMISSÃO | AK17: COMISSÃO | AL17: OBSERVAÇÃO | AN17: 41548 | AO17: 2980.45 | AP17: 980.45 | AQ17: 41691 | AR17: -2000
X18: CLIENTE | Y18: PEDIDO | AB18: UND | AC18: CLIENTE | AD18: ENTREGA | AE18: FATURA | AJ18: 35 DD | AK18: R$ | AP18: 2000 | AQ18: 07/03/2014 | AR18: 0
P19: =SUM(P7:P18) -> 86355.4 | R19: =(P19*0.05) -> 4317.77 | S19: OK | AN19: 41579 | AO19: 0 | AP19: 0 | AR19: 0
V20: CUMBUCA 500 - MA 15 | W20: 1 | X20: E-MAIL | Y20: 42672 | Z20: 5 | AA20: MIL | AB20: 305 | AD20: 42683 | AE20: 42674 | AF20: 1462 | AG20: 5000 | AH20: =(AG20-Z20*1000) -> 0 | AI20: =(AG20*AB20/1000) -> 1525 | AJ20: =(AE20+35) -> 42709 | AK20: =(AI20*0.05) -> 76.25 | AN20: 41609 | AO20: 2701.45 | AP20: 2701.45 | AQ20: 03/04/2014 | AR20: 0
B21: FEVEREIRO 2016 | AN21: 41640 | AO21: 2689.47 | AP21: 2689.47 | AQ21: 41754 | AR21: 0
E22: OC | F22: DATA | I22: PREÇO | J22: CODIGO | K22: DATA | L22: DATA | Q22: DATA | R22: VALOR DA | AN22: 41671 | AO22: 1738.8 | AP22: 1738.8 | AQ22: 08/05/2014 | AR22: 0
B23: CLIENTE | C23: PRODUTO | D23: PEDIDO | E23: DO | F23: DO | G23: QUANT | H23: UND | I23: POR | J23: DO | K23: DE | L23: DE | M23: N F | N23: QUANT | O23: SALDO | P23: VALOR | Q23: COMISSÃO | R23: COMISSÃO | S23: OBSERVAÇÃO | AN23: 41699 | AO23: 4137.87 | AP23: 2137.87 | AQ23: 23/05/2014 | AR23: -2000
E24: CLIENTE | F24: PEDIDO | I24: UND | J24: CLIENTE | K24: ENTREGA | L24: FATURA | Q24: 30 DD | R24: R$ | AP24: 2000 | AQ24: 20/06/2014 | AR24: 0
B25: NORTEFRUT | C25: BANDEJA PAPAYA PET 4 UND | D25: 46 | E25: e-mail | F25: 42384 | G25: 20 | H25: MIL | I25: 449.5 | K25: 42373 | L25: 42376 | M25: 2641 | N25: 20000 | O25: =(N25-G25*1000) -> 0 | P25: =(N25*I25/1000) -> 8990 | Q25: =(L25+28) -> 42404 | R25: =(P25*0.05) -> 449.5 | AN25: 41730 | AO25: 4229.4 | AP25: 2000 | AQ25: 41834 | AR25: -2229.4
B26: FF MAGALHÃES | C26: BANDEJA PET PAPAYA 4 UND. | D26: 5 | E26: E-MAIL | F26: 42271 | G26: 10 | H26: MIL | I26: 449.5 | K26: 42384 | L26: 42384 | M26: 2646 | N26: 10000 | O26: =(N26-G26*1000) -> 0 | P26: =(N26*I26/1000) -> 4495 | Q26: =(L26+10) -> 42394 | R26: =(P26*0.05) -> 224.75 | AP26: 2229.4 | AQ26: 18/07/2014 | AR26: 0
B27: TERRA | C27: CUMBUCA 500 G - 35 | D27: 11 | E27: verbal | F27: 42381 | G27: 5 | H27: MIL | I27: 279 | K27: 42381 | L27: 42381 | M27: 2645 | N27: 5000 | O27: =(N27-G27*1000) -> 0 | P27: =(N27*I27/1000) -> 1395 | Q27: =(L27+28) -> 42409 | R27: =(P27*0.05) -> 69.75 | AN27: 41760 | AO27: 3332.1 | AP27: 2000 | AQ27: 41859 | AR27: =(AP27-AO27) -> -1332.1
B28: Q'DELICIA | C28: BANDEJAS MAMÃO PAPAYA 4 UND | D28: 21 | E28: E-MAIL | F28: 42389 | G28: 3 | H28: MIL | I28: 449.5 | K28: 42390 | L28: 42389 | M28: 2652 | N28: 3200 | O28: =(N28-G28*1000) -> 200 | P28: =(N28*I28/1000) -> 1438.4 | Q28: =(L28+35) -> 42424 | R28: =(P28*0.05) -> 71.92 | V28: ALLCAB FIOS E CABOS - BRASIL SUL | W28: CAIO G. PAVANELLI (11) 2455-2011 | AP28: 1332.1 | AQ28: 27/08/2014 | AR28: 0
B29: Q'DELICIA | C29: CUMBUCA 500 G 35 | D29: 22 | E29: E-MAIL | F29: 42389 | G29: 5 | H29: MIL | I29: 300 | K29: 42390 | L29: 42389 | M29: 2652 | N29: 5000 | O29: =(N29-G29*1000) -> 0 | P29: =(N29*I29/1000) -> 1500 | Q29: =(L29+35) -> 42424 | R29: =(P29*0.05) -> 75 | X29: OC | Y29: DATA | AB29: PREÇO | AC29: CODIGO | AD29: DATA | AE29: DATA | AJ29: DATA | AK29: VALOR DA | AN29: 41791 | AO29: 4538.6 | AP29: 2000 | AQ29: 04/09/2014 | AR29: =(AP29-AO29) -> -2538.6
B30: Q'DELICIA | C30: BANDEJAS MAMÃO PAPAYA 2 UND | D30: 23 | E30: E-MAIL | F30: 42389 | G30: 5 | H30: MIL | I30: 320 | K30: 42390 | L30: 42389 | M30: 2652 | N30: 5000 | O30: =(N30-G30*1000) -> 0 | P30: =(N30*I30/1000) -> 1600 | Q30: =(L30+35) -> 42424 | R30: =(P30*0.05) -> 80 | V30: PRODUTO | W30: PEDIDO | X30: DO | Y30: DO | Z30: QUANT | AA30: UND | AB30: POR | AC30: DO | AD30: DE | AE30: DE | AF30: N F | AG30: QUANT | AH30: SALDO | AI30: VALOR | AJ30: COMISSÃO | AK30: COMISSÃO | AL30: OBSERVAÇÃO | AP30: 2358.6 | AQ30: 18/09/2014 | AR30: =(AP30+AR29) -> -180
B31: DOCE MEL | C31: =IF(J31=1473,"BANDEJA PAPAYA PET - GF 15",IF(J31=0," ")) -> BANDEJA PAPAYA PET - GF 15 | D31: 31 | E31: 22007 | F31: 42391 | G31: 50 | H31: MIL | I31: 449.5 | J31: 1473 | K31: 42399 | L31: 42397 | M31: 2658 | N31: 50000 | O31: =(N31-G31*1000) -> 0 | P31: =(N31*I31/1000) -> 22475 | Q31: =(L31+30) -> 42427 | R31: =(P31*0.05) -> 1123.75 | X31: CLIENTE | Y31: PEDIDO | AB31: UND | AC31: CLIENTE | AD31: ENTREGA | AE31: FATURA | AJ31: 35 DD | AK31: R$ | AP31: 3000 | AQ31: 41927 | AR31: =(AP31+AR30) -> 2820
B32: BELLO FRUIT | C32: BANDEJA CLAIM SHELL PAPAYA 4 UND | D32: 8 | E32: e-mail | F32: 42384 | G32: 12 | H32: MIL | I32: 449.5 | K32: 42387 | L32: 42391 | M32: 2653 | N32: 12000 | O32: =(N32-G32*1000) -> 0 | P32: =(N32*I32/1000) -> 5394 | Q32: =(L32+35) -> 42426 | R32: =(P32*0.05) -> 269.7 | AN32: 41821 | AO32: 4997.93 | AP32: 2820 | AQ32: 15/10/2014 | AR32: =(AP32-AO32) -> -2177.93
V33: FILME PVC EST. 60 MM X 40 MICRA | W33: 1 | X33: E-MAIL | Y33: 42782 | Z33: 300 | AA33: KG | AB33: 9.7 | AD33: 42788 | AE33: 42794 | AF33: 46329 | AG33: 310 | AH33: =(AG33-Z33) -> 10 | AI33: =(AG33*AB33) -> 3007 | AJ33: =(AE33+28) -> 42822 | AK33: =(AI33*0.05) -> 150.35 | AP33: 4044.9 | AQ33: 30/10/2014 | AR33: =(AP33+AR32) -> 1866.97
P34: =SUM(P25:P33) -> 47287.4 | R34: =(P34*0.05) -> 2364.37 | S34: OK | AN34: 41852 | AO34: 2584.4 | AP34: 2584.4 | AQ34: 03/10/2014 | AR34: =(AP34-AO34) -> 0
AN35: 41883 | AO35: 5896.64 | AP35: 1866.97 | AQ35: 30/10/2014 | AR35: =(AP35-AO35) -> -4029.67
B36: MARÇO 2016 | AP36: 3896.64 | AQ36: 18/11/2014 | AR36: =(AP36+AR35) -> -133.03
E37: OC | F37: DATA | I37: PREÇO | J37: CODIGO | K37: DATA | L37: DATA | Q37: DATA | R37: VALOR DA | AP37: 2000 | AQ37: 41976 | AR37: =(AP37+AR36) -> 1866.97
B38: CLIENTE | C38: PRODUTO | D38: PEDIDO | E38: DO | F38: DO | G38: QUANT | H38: UND | I38: POR | J38: DO | K38: DE | L38: DE | M38: N F | N38: QUANT | O38: SALDO | P38: VALOR | Q38: COMISSÃO | R38: COMISSÃO | S38: OBSERVAÇÃO | AN38: 41913 | AO38: 9827.6 | AP38: 1866.97 | AQ38: 41976 | AR38: =(AP38-AO38) -> -7960.63
E39: CLIENTE | F39: PEDIDO | I39: UND | J39: CLIENTE | K39: ENTREGA | L39: FATURA | Q39: 30 DD | R39: R$ | AP39: 3000 | AQ39: 12/12/2014 | AR39: =(AP39+AR38) -> -4960.63
B40: CASA DA UVA | C40: CUMBUCA 500 - G 35 | D40: 6 | E40: E-MAIL | F40: 42398 | G40: 12 | H40: MIL | I40: 300 | K40: 42402 | L40: 42403 | M40: 2663 | N40: 12000 | O40: =(N40-G40*1000) -> 0 | P40: =(N40*I40/1000) -> 3600 | Q40: =(L40+35) -> 42438 | R40: =(P40*0.05) -> 180 | AP40: 2500 | AQ40: 05/01/2015 | AR40: =(AP40+AR39) -> -2460.63
B41: CASA SUIÇA | C41: BANDEJAS BOLO COBERTO/ZERO | D41: 280 | E41: E-MAIL | F41: 42383 | G41: 100 | H41: MIL | I41: 66 | J41: 13383 | K41: 42402 | L41: 42401 | M41: 2660 | N41: 102000 | O41: =(N41-G41*1000) -> 2000 | P41: =(N41*I41/1000) -> 6732 | Q41: =(L41+35) -> 42436 | R41: =(P41*0.05) -> 336.6 | AP41: 2327.6 | AQ41: 05/01/2015 | AR41: =(AP41+AR40) -> -133.03
B42: CASA SUIÇA | C42: BANDEJA RETANGULAR - JANDIRA | D42: 281 | E42: E-MAIL | F42: 42383 | G42: 200 | H42: MIL | I42: 66 | J42: 9124 | K42: 42402 | L42: 42401 | M42: 2660 | N42: 201000 | O42: =(N42-G42*1000) -> 1000 | P42: =(N42*I42/1000) -> 13266 | Q42: =(L42+35) -> 42436 | R42: =(P42*0.05) -> 663.3 | AP42: 289.97 | AQ42: 42009 | AR42: =(AP42+AR41) -> 156.94
...

Sheet 2018
S2: MAPA DE COMISSÃO | AC2: SERRAPLAST TRANSFORMAÇÃO E COMERCIO DE PLASTICO LTDA. | AN2: MAPA DE ENTREGAS | BP2: BRASIL SUL EMBALAGENS LTDA. | CU2: CCS INDUSTRIA E COMERCIO DE EMBALAGENS PLASTICAS LTDA. | EG2: EDIPRINT INDUSTRIA GRAFICA LTDA.
F3: MAPA GERAL DE COMISSÕES
B4: 2017 | P4: SERRAPLAST JANEIRO 2017 | V4: COMISSÕES MENSAIS | BA4: BRASIL SUL MARÇO 2017 | BT4: ANA BEATRIZ S. BENTO | BU4: AILTON SOARES DE LIMA 11 96533-5312 | CK4: CCS MARÇO 2018 | DE4: SUPERBOM | DF4: MISAEL KAYSER/ELIZETE MELO 11 2842-1807 EVALDO 11 99864-9953 | DW4: EDIPRINT OUTUBRO 2021 | EP4: HORTA VITAE | EQ4: RENATO BOARO CAMILA 14 3812-7000
B5: REPRESENTADA | C5: JAN 12 | D5: FEV 01 | E5: MAR 02 | F5: ABR 03 | G5: MAI 04 | H5: JUN 05 | I5: JUL 06 | J5: AGO 07 | K5: SET 08 | L5: OUT 09 | M5: NOV 10 | N5: DEZ 11 | S5: OC | T5: DATA | W5: PREÇO | X5: CODIGO | Y5: DATA | Z5: DATA | AE5: VALOR DA | AJ5: BENASSI CAMPINAS | AK5: LUCIANA 19 3307-7843 RAMAL 218 | BD5: OC | BE5: DATA | BH5: PREÇO | BI5: CODIGO | BJ5: DATA | BK5: DATA | BP5: VALOR DA | BV5: OC | BW5: DATA | BZ5: PREÇO | CA5: CODIGO | CB5: DATA | CC5: DATA | CH5: VALOR DA | CN5: OC | CO5: DATA | CR5: PREÇO | CS5: CODIGO | CT5: DATA | CU5: DATA | CZ5: DATA | DA5: VALOR DA | DG5: OC | DH5: DATA | DK5: PREÇO | DL5: CODIGO | DM5: DATA | DN5: DATA | DS5: DATA | DT5: VALOR DA | DZ5: OC | EA5: DATA | ED5: PREÇO | EE5: CODIGO | EF5: DATA | EG5: DATA | EL5: DATA | EM5: VALOR DA | ER5: OC | ES5: DATA | EV5: PREÇO | EW5: CODIGO | EX5: DATA | EY5: DATA | FD5: DATA | FE5: VALOR DA
P6: CLIENTE | Q6: PRODUTO | R6: PEDIDO | S6: DO | T6: DO | U6: QUANT | V6: UND | W6: POR | X6: DO | Y6: DE | Z6: DE | AA6: N F | AB6: QUANT | AC6: SALDO | AD6: VALOR | AE6: COMISSÃO | AF6: OBSERVAÇÃO | AL6: OC | AM6: DATA | AP6: PREÇO | AQ6: CODIGO | AR6: DATA | AS6: DATA | AX6: VALOR DA | BA6: CLIENTE | BB6: PRODUTO | BC6: PEDIDO | BD6: DO | BE6: DO | BF6: QUANT | BG6: UND | BH6: POR | BI6: DO | BJ6: DE | BK6: DE | BL6: N F | BM6: QUANT | BN6: SALDO | BO6: VALOR | BP6: COMISSÃO | BQ6: OBSERVAÇÃO | BT6: PRODUTO | BU6: PEDIDO | BV6: DO | BW6: DO | BX6: QUANT | BY6: UND | BZ6: POR | CA6: DO | CB6: DE | CC6: DE | CD6: N F | CE6: QUANT | CF6: SALDO | CG6: VALOR | CH6: COMISSÃO | CI6: OBSERVAÇÃO | CK6: CLIENTE | CL6: PRODUTO | CM6: PEDIDO | CN6: DO | CO6: DO | CP6: QUANT | CQ6: UND | CR6: POR | CS6: DO | CT6: DE | CU6: DE | CV6: N F | CW6: QUANT | CX6: SALDO | CY6: VALOR | CZ6: COMISSÃO | DA6: COMISSÃO | DB6: OBSERVAÇÃO | DE6: PRODUTO | DF6: PEDIDO | DG6: DO | DH6: DO | DI6: QUANT | DJ6: UND | DK6: POR | DL6: DO | DM6: DE | DN6: DE | DO6: N F | DP6: QUANT | DQ6: SALDO | DR6: VALOR | DS6: COMISSÃO | DT6: COMISSÃO | DU6: OBSERVAÇÃO | DW6: CLIENTE | DX6: PRODUTO | DY6: PEDIDO | DZ6: DO | EA6: DO | EB6: QUANT | EC6: UND | ED6: POR | EE6: DO | EF6: DE | EG6: DE | EH6: N F | EI6: QUANT | EJ6: SALDO | EK6: VALOR | EL6: COMISSÃO | EM6: COMISSÃO | EN6: OBSERVAÇÃO | EP6: PRODUTO | EQ6: PEDIDO | ER6: DO | ES6: DO | ET6: QUANT | EU6: UND | EV6: POR | EW6: DO | EX6: DE | EY6: DE | EZ6: N F | FA6: QUANT | FB6: SALDO | FC6: VALOR | FD6: COMISSÃO | FE6: COMISSÃO | FF6: OBSERVAÇÃO
B7: SERRAPLAST | C7: =(AE17) -> 4385.6 | D7: =(AE28) -> 818.75 | E7: =(AE40) -> 1451.4 | F7: =(AE50) -> 1879 | G7: =(AE64) -> 4019.5 | H7: =(AE80) -> 3086.35 | I7: =(AE93) -> 1933 | J7: =(AE113) -> 3556.9 | K7: =(AE130) -> 5245 | L7: =(AE141) -> 232.75 | M7: =(AE162) -> 8301 | N7: =(AE181) -> 7359.5 | S7: CLIENTE | T7: PEDIDO | W7: UND | X7: CLIENTE | Y7: ENTREGA | Z7: FATURA | AE7: R$ | AJ7: PRODUTO | AK7: PEDIDO | AL7: DO | AM7: DO | AN7: QUANTIDADE | AO7: UND | AP7: POR | AQ7: DO | AR7: DE | AS7: DE | AT7: N F | AU7: QUANTIDADE | AV7: SALDO | AW7: VALOR | AX7: COMISSÃO | AY7: OBSERVAÇÃO | BD7: CLIENTE | BE7: PEDIDO | BH7: UND | BI7: CLIENTE | BJ7: ENTREGA | BK7: FATURA | BP7: R$ | BV7: CLIENTE | BW7: PEDIDO | BZ7: UND | CA7: CLIENTE | CB7: ENTREGA | CC7: FATURA | CH7: R$ | CN7: CLIENTE | CO7: PEDIDO | CR7: UND | CS7: CLIENTE | CT7: ENTREGA | CU7: FATURA | CZ7: 30 DD | DA7: R$ | DG7: CLIENTE | DH7: PEDIDO | DK7: UND | DL7: CLIENTE | DM7: ENTREGA | DN7: FATURA | DS7: 42 DD | DT7: R$ | DZ7: CLIENTE | EA7: PEDIDO | ED7: UND | EE7: CLIENTE | EF7: ENTREGA | EG7: FATURA | EL7: 30 DD | EM7: R$ | ER7: CLIENTE | ES7: PEDIDO | EV7: UND | EW7: CLIENTE | EX7: ENTREGA | EY7: FATURA | FD7: 42 DD | FE7: R$
P8: KORIN AGRO | Q8: EMB. OVO GALINHA 10 UND SRG - C10 | R8: 8 | S8: 31524 | T8: 42685 | U8: 120 | V8: MIL | W8: 255 | Y8: 42723 | Z8: 42714 | AA8: 1562 | AB8: 120000 | AC8: =(AB8-U8*1000) -> 0 | AD8: =(AB8*W8/1000) -> 30600 | AE8: =(AD8*0.05) -> 1530 | AF8: PAGO | AL8: CLIENTE | AM8: PEDIDO | AP8: UND | AQ8: CLIENTE | AR8: ENTREGA | AS8: FATURA | AX8: R$ | BA8: GO GREEN | BB8: FILME PVC GA 380 X 10 X 1200 | BC8: 1 | BD8: VERBAL | BE8: 42765 | BF8: 50 | BG8: BOB | BH8: 52.9 | BJ8: 42769 | BK8: 42773 | BL8: 46126 | BM8: 54 | BN8: =(BM8-BF8) -> 4 | BO8: =(BM8*BH8) -> 2856.6 | BP8: =(BO8*0.05) -> 142.83 | BQ8: PAGO | BT8: FILME PVC GA 380 X 9 X 1000 | BU8: 1 | BV8: VERBAL | BW8: 43733 | BX8: 10 | BY8: BOB | BZ8: 51.43 | CB8: 43749 | CC8: 43749 | CD8: 56395 | CE8: 12 | CF8: =(CE8-BX8) -> 2 | CG8: =(CE8*BZ8) -> 617.16 | CH8: =(CG8*0.05) -> 30.858 | CK8: SUPERBOM | CL8: CONJUNTO ENVASE MEL 200G | CM8: 131 | CO8: 43125 | CP8: 45 | CQ8: MIL | CR8: 868.82 | CT8: 43151 | CU8: =(CT8) -> 43151 | CV8: 13182/13191 | CW8: 45100 | CX8: =(CP8*1000-CW8) -> -100 | CY8: =(CR8*CW8/1000) -> 39183.782 | CZ8: =(CU8+42) -> 43193 | DA8: =(CY8*0.03) -> 1175.5135
B9: CHROMO | P9: CASA DA UVA | Q9: CUMBUCA 500 G - MA 15 | R9: 2 | S9: VERBAL | T9: 42709 | U9: 15 | V9: MIL | W9: 315 | Y9: 42714 | Z9: 42716 | AA9: 1564 | AB9: 15000 | AC9: =(AB9-U9*1000) -> 0 | AD9: =(AB9*W9/1000) -> 4725 | AE9: =(AD9*0.05) -> 236.25 | AF9: PAGO | AJ9: CUMBUCA 500 G - MA15 | AK9: 1 | AL9: VERBAL | AM9: 42432 | AN9: 30 | AO9: MIL | AP9: 315 | AR9: 42437 | AS9: 42437 | AT9: 8396 | AU9: 30000 | AV9: =(AU9-AN9*1000) -> 0 | AW9: =(AU9*AP9/1000) -> 9450 | AX9: =(AW9*0.05) -> 472.5 | BA9: ALL CAB | BB9: FILME PVC EST. 60 MM X 40 MICRA | BC9: 1 | BD9: E-MAIL | BE9: 42782 | BF9: 300 | BG9: KG | BH9: 9.7 | BJ9: 42788 | BK9: 42794 | BL9: 46329 | BM9: 310 | BN9: =(BM9-BF9) -> 10 | BO9: =(BM9*BH9) -> 3007 | BP9: =(BO9*0.05) -> 150.35 | BQ9: PAGO | BT9: FILME PVC GA 300 X 9 X 1000 | BU9: 1 | BV9: VERBAL | BW9: 43733 | BX9: 30 | BY9: BOB | BZ9: 40.65 | CB9: 43749 | CC9: 43749 | CD9: 56395 | CE9: 32 | CF9: =(CE9-BX9) -> 2 | CG9: =(CE9*BZ9) -> 1300.8 | CH9: =(CG9*0.05) -> 65.04 | DE9: CONJUNTO ENVASE MEL 200G | DF9: 125 | DH9: 42769 | DI9: 45 | DJ9: Mil | DK9: 842.76 | DM9: 42794 | DN9: 42793 | DO9: 12618 | DP9: 45000 | DQ9: =(DI9*1000-DP9) -> 0 | DR9: =(DK9*DP9/1000) -> 37924.2 | DS9: =(DN9+42) -> 42835 | DT9: =(DR9*0.03) -> 1137.726 | EP9: ETIQUETA ADESIVA OVO CAIPIRA TG 20 UND | EQ9: 1 | ER9: E-MAIL | ES9: 44469 | ET9: 30 | EU9: MIL | EV9: 145.65 | EX9: 44480 | EY9: 44480 | FA9: 30000 | FB9: =(FA9-ET9*1000) -> 0 | FC9: =(FA9*EV9/1000) -> 4369.5 | FE9: =(FC9*0.04) -> 174.78
P10: CASA DA UVA | Q10: EMBALAGEM TOMATINHO - SRT 08 | R10: 3 | S10: VERBAL | T10: 42709 | U10: 10 | V10: MIL | W10: 153.7 | Y10: 42714 | Z10: 42716 | AA10: 1564 | AB10: 10000 | AC10: =(AB10-U10*1000) -> 0 | AD10: =(AB10*W10/1000) -> 1537 | AE10: =(AD10*0.05) -> 76.85 | AF10: PAGO | AJ10: CUMBUCA 500 G - MA15 | AK10: 2 | AL10: VERBAL | AM10: 42503 | AN10: 50 | AO10: MIL | AP10: 315 | AR10: 42504 | AS10: 42504 | AT10: 8580 | AU10: 50000 | AV10: =(AU10-AN10*1000) -> 0 | AW10: =(AU10*AP10/1000) -> 15750 | AX10: =(AW10*0.05) -> 787.5 | BA10: LOSCHI & WATANABE | BB10: FILME PVC GA 380 X 10 X 1000 | BC10: 1 | BD10: VERBAL | BE10: 42787 | BF10: 50 | BG10: BOB | BH10: 45 | BJ10: 42790 | BK10: 42794 | BL10: 46332 | BM10: 54 | BN10: =(BM10-BF10) -> 4 | BO10: =(BM10*BH10) -> 2430 | BP10: =(BO10*0.05) -> 121.5 | BQ10: PAGO | BT10: FILME PVC GA 380 X 9 X 1000 | BU10: 2 | BV10: VERBAL | BW10: 44026 | BX10: 10 | BY10: BOB | BZ10: 53.48 | CB10: 44033 | CC10: 44040 | CD10: 59159 | CE10: 12 | CF10: =(CE10-BX10) -> 2 | CG10: =(CE10*BZ10) -> 641.76 | CH10: =(CG10*0.05) -> 32.088 | DE10: CONJUNTO ENVASE MEL 200G | DF10: 126 | DH10: 42769 | DI10: 45 | DJ10: Mil | DK10: 842.76 | DM10: 42828 | DN10: 42849 | DO10: 12801 | DP10: 45000 | DQ10: =(DI10*1000-DP10) -> 0 | DR10: =(DK10*DP10/1000) -> 37924.2 | DS10: =(DN10+42) -> 42891 | DT10: =(DR10*0.03) -> 1137.726
B11: CCS | E11: =(DA15) -> 1175.5135 | F11: =(DA28) -> 1210.7997 | G11: =(DA49) -> 1208.115 | H11: =(DA62) -> 0 | I11: =(DA75) -> 1245.375 | J11: 1140.27 | K11: =(DA103) -> 1245.375 | L11: =(DA117) -> 0 | M11: 1137.73 | N11: =(DA143) -> 1329.075 | P11: CACO | Q11: CUMBUCA 500 G - MA 15 | R11: 5 | S11: VERBAL | T11: 42709 | U11: 10 | V11: MIL | W11: 315 | Y11: 42716 | Z11: 42716 | AA11: 1566 | AB11: 10000 | AC11: =(AB11-U11*1000) -> 0 | AD11: =(AB11*W11/1000) -> 3150 | AE11: =(AD11*0.05) -> 157.5 | AF11: PAGO | AJ11: CUMBUCA 500 G - MA15 | AK11: 3 | AL11: VERBAL | AM11: 42682 | AN11: 10 | AO11: MIL | AP11: 305 | AR11: 42685 | AS11: 42688 | AT11: 1476 | AU11: 10000 | AV11: =(AU11-AN11*1000) -> 0 | AW11: =(AU11*AP11/1000) -> 3050 | AX11: =(AW11*0.05) -> 152.5 | BT11: FILME PVC GA 300 X 9 X 1000 | BU11: 2 | BV11: VERBAL | BW11: 44026 | BX11: 20 | BY11: BOB | BZ11: 42.27 | CB11: 44033 | CC11: 44040 | CD11: 59159 | CE11: 24 | CF11: =(CE11-BX11) -> 4 | CG11: =(CE11*BZ11) -> 1014.48 | CH11: =(CG11*0.05) -> 50.724 | DE11: CONJUNTO ENVASE MEL 200G | DF11: 127 | DH11: 42769 | DI11: 45 | DJ11: Mil | DK11: 842.76 | DM11: 42857 | DN11: 42857 | DP11: 45000 | DQ11: =(DI11*1000-DP11) -> 0 | DR11: =(DK11*DP11/1000) -> 37924.2 | DS11: =(DN11+42) -> 42899 | DT11: =(DR11*0.03) -> 1137.726
P12: AURORA | Q12: CUMBUCA 500 G - MA 15 | R12: 2 | S12: E-MAIL | T12: 42711 | U12: 10 | V12: MIL | W12: 335 | Y12: 42716 | Z12: 42716 | AA12: 1567 | AB12: 10000 | AC12: =(AB12-U12*1000) -> 0 | AD12: =(AB12*W12/1000) -> 3350 | AE12: =(AD12*0.05) -> 167.5 | AF12: PAGO | AJ12: CUMBUCA 500 G - MA15 | AK12: 4 | AL12: E-MAIL | AM12: 42686 | AN12: 200 | AO12: MIL | AP12: 300 | AR12: 42691 | AS12: 42688 | AT12: 1467 | AU12: 200000 | AV12: =(AU12-AN12*1000) -> 0 | AW12: =(AU12*AP12/1000) -> 60000 | AX12: =(AW12*0.05) -> 3000 | BO12: =SUM(BO8:BO10) -> 8293.6 | BP12: =(BO12*0.05) -> 414.68 | DE12: CONJUNTO ENVASE MEL 200G | DF12: 128 | DH12: 42769 | DI12: 45 | DJ12: MIL | DK12: 842.76 | DM12: 42892 | DN12: 42892 | DP12: 45000 | DQ12: =(DI12*1000-DP12) -> 0 | DR12: =(DK12*DP12/1000) -> 37924.2 | DS12: =(DN12+42) -> 42934 | DT12: =(DR12*0.03) -> 1137.726
B13: BRASIL SUL | E13: =(BP12) -> 414.68 | F13: 0 | G13: =(BP40) -> 1923.8459 | H13: =(BP51) -> 931.49976 | I13: =(BP59) -> 150.6666 | J13: =(BP70) -> 640.37392 | K13: =(BP80) -> 123.538 | L13: =(BP96) -> 1174.8885 | M13: =(BP106) -> 504.33 | N13: =(BP114) -> 217.5 | P13: BIANCHI | Q13: EMB. OVO GALINHA 10 UND SRG - C10 | R13: 4 | S13: verbal | T13: 42712 | U13: 20 | V13: MIL | W13: 255 | Y13: 42716 | Z13: 42714 | AA13: 1563 | AB13: 20000 | AC13: =(AB13-U13*1000) -> 0 | AD13: =(AB13*W13/1000) -> 5100 | AE13: =(AD13*0.05) -> 255 | AF13: PAGO | AJ13: CUMBUCA 500 G - MA15 | AK13: 5 | AL13: VERBAL | AM13: 42916 | AN13: 30 | AO13: MIL | AP13: 300 | AR13: 42922 | AS13: 42919 | AT13: 2066 | AU13: 30000 | AV13: =(AU13-AN13*1000) -> 0 | AW13: =(AU13*AP13/1000) -> 9000 | AX13: =(AW13*0.05) -> 450 | DE13: CONJUNTO ENVASE MEL 200G | DF13: 129 | DH13: 42971 | DI13: 45 | DJ13: MIL | DK13: 842.76 | DM13: 42975 | DN13: 42975 | DP13: 45000 | DQ13: =(DI13*1000-DP13) -> 0 | DR13: =(DK13*DP13/1000) -> 37924.2 | DS13: =(DN13+42) -> 43017 | DT13: =(DR13*0.03) -> 1137.726
P14: MAPE | Q14: CUMBUCA 500 G - MA15 | R14: 7 | S14: verbal | T14: 42718 | U14: 50 | V14: MIL | W14: 305 | Y14: 42725 | Z14: 42719 | AA14: 1593 | AB14: 50000 | AC14: =(AB14-U14*1000) -> 0 | AD14: =(AB14*W14/1000) -> 15250 | AE14: 750 | AF14: PAGO | AJ14: CUMBUCA 500 G - MA15 CRISTAL | AK14: 6 | AL14: VERBAL | AM14: 43392 | AN14: 100 | AO14: MIL | AP14: 290 | AR14: 43402 | AS14: 43399 | AT14: 3383 | AU14: 100000 | AV14: =(AU14-AN14*1000) -> 0 | AW14: =(AU14*AP14/1000) -> 29000 | AX14: =(AW14*0.05) -> 1450 | BA14: BRASIL SUL ABRIL 2017 | DE14: CONJUNTO ENVASE MEL 200G | DF14: 130 | DH14: 43019 | DI14: 45 | DJ14: MIL | DK14: 868.82 | DM14: 43056 | DN14: 43056 | DP14: 45000 | DQ14: =(DI14*1000-DP14) -> 0 | DR14: =(DK14*DP14/1000) -> 39096.9 | DS14: =(DN14+42) -> 43098 | DT14: =(DR14*0.03) -> 1172.907
P15: LOSCHI & WATANABE | Q15: CUMBUCA 500 G - MA 15 | R15: 2 | S15: verbal | T15: 42720 | U15: 80 | V15: MIL | W15: 300 | Y15: 42725 | Z15: 42723 | AA15: 1602 | AB15: 80000 | AC15: =(AB15-U15*1000) -> 0 | AD15: =(AB15*W15/1000) -> 24000 | AE15: =(AD15*0.05) -> 1200 | AF15: PAGO | AJ15: CUMBUCA 500 G - MA15 CRISTAL | AK15: 7 | AL15: VERBAL | AM15: 43392 | AN15: 100 | AO15: MIL | AP15: 290 | AR15: 43437 | AS15: 43438 | AT15: 10636 | AU15: 50000 | AV15: =(AU15-AN15*1000) -> -50000 | AW15: =(AU15*AP15/1000) -> 14500 | AX15: =(AW15*0.05) -> 725 | BD15: OC | BE15: DATA | BH15: PREÇO | BI15: CODIGO | BJ15: DATA | BK15: DATA | BP15: VALOR DA | CY15: =SUM(CY8:CY14) -> 39183.782 | DA15: =SUM(DA8:DA14) -> 1175.5135 | DE15: CONJUNTO ENVASE MEL 200G | DF15: 131 | DH15: 43125 | DI15: 45 | DJ15: MIL | DK15: 868.82 | DM15: 43151 | DN15: =(DM15) -> 43151 | DO15: 13182/13191 | DP15: 45100 | DQ15: =(DI15*1000-DP15) -> -100 | DR15: =(DK15*DP15/1000) -> 39183.782 | DS15: =(DN15+42) -> 43193 | DT15: =(DR15*0.03) -> 1175.5135
AJ16: CUMBUCA 500 G - MA15 CRISTAL | AK16: 7 | AL16: VERBAL | AM16: 43392 | AN16: 50 | AO16: MIL | AP16: 290 | AR16: 43437 | AS16: 43437 | AU16: 50000 | AV16: =(AU16-AN16*1000) -> 0 | AW16: =(AU16*AP16/1000) -> 14500 | AX16: =(AW16*0.05) -> 725 | AY16: CANCELADO | BA16: CLIENTE | BB16: PRODUTO | BC16: PEDIDO | BD16: DO | BE16: DO | BF16: QUANT | BG16: UND | BH16: POR | BI16: DO | BJ16: DE | BK16: DE | BL16: N F | BM16: QUANT | BN16: SALDO | BO16: VALOR | BP16: COMISSÃO | BQ16: OBSERVAÇÃO | DE16: CONJUNTO ENVASE MEL 200G | DF16: 132 | DH16: 43125 | DI16: 45 | DJ16: MIL | DK16: 894.9 | DM16: 43179 | DN16: 43182 | DO16: 13255 | DP16: 45000 | DQ16: =(DI16*1000-DP16) -> 0 | DR16: 40359.99 | DS16: =(DN16+42) -> 43224 | DT16: =(DR16*0.03) -> 1210.7997
AD17: =SUM(AD8:AD16) -> 87712 | AE17: =(AD17*0.05) -> 4385.6 | AJ17: CUMBUCA 500 G - MA15 CRISTAL | AK17: 8 | AL17: VERBAL | AM17: 43549 | AN17: 30 | AO17: MIL | AP17: 290 | AR17: 43556 | AS17: 43573 | AT17: 3749 | AU17: 30000 | AV17: =(AU17-AN17*1000) -> 0 | AW17: =(AU17*AP17/1000) -> 8700 | AX17: =(AW17*0.05) -> 435 | BD17: CLIENTE | BE17: PEDIDO | BH17: UND | BI17: CLIENTE | BJ17: ENTREGA | BK17: FATURA | BP17: R$ | CG17: =SUM(CG8:CG16) -> 3574.2 | CH17: =SUM(CH8:CH16) -> 178.71 | CK17: CCS ABRIL 2018 | DE17: CONJUNTO ENVASE MEL 200G | DF17: 133 | DH17: 43125 | DI17: 45 | DJ17: MIL | DK17: 894.9 | DM17: 43214 | DN17: 43217 | DO17: 13315 | DP17: 45000 | DQ17: =(DI17*1000-DP17) -> 0 | DR17: =(DK17*DP17/1000) -> 40270.5 | DS17: =(DN17+42) -> 43259 | DT17: =(DR17*0.03) -> 1208.115 | DW17: EDIPRINT NOVEMBRO 2021
B18: TOTAL | C18: =SUM(C7:C17) -> 4385.6 | D18: =SUM(D7:D17) -> 818.75 | E18: =SUM(E7:E17) -> 3041.5935 | F18: =SUM(F7:F17) -> 3089.7997 | G18: =SUM(G7:G17) -> 7151.4609 | H18: =(H7+H11+H13) -> 4017.8498 | I18: =SUM(I7:I17) -> 3329.0416 | J18: =SUM(J7:J17) -> 5337.5439 | K18: =SUM(K7:K17) -> 6613.913 | L18: =SUM(L7:L17) -> 1407.6385 | M18: =SUM(M7:M17) -> 9943.06 | N18: =SUM(N7:N17) -> 8906.075 | O18: =SUM(C18:N18) -> 58042.326 | AJ18: CUMBUCA 500 G - MA15 CRISTAL | AK18: 9 | AL18: VERBAL | AM18: 43621 | AN18: 40 | AO18: MIL | AP18: 276 | AR18: 43626 | AS18: 43623 | AT18: 3813 | AU18: 40000 | AV18: =(AU18-AN18*1000) -> 0 | AW18: =(AU18*AP18/1000) -> 11040 | AX18: =(AW18*0.05) -> 552 | BT18: CABELAUTO | BU18: THIAGO NUNES - 35 3629-2500 / 2544 | CA18: CAUÃ | CN18: OC | CO18: DATA | CR18: PREÇO | CS18: CODIGO | CT18: DATA | CU18: DATA | CZ18: DATA | DA18: VALOR DA | DE18: CONJUNTO ENVASE MEL 200G | DF18: 134 | DH18: 43125 | DI18: 45 | DJ18: MIL | DK18: 922.5 | DM18: 43255 | DN18: 43255 | DO18: 13367 | DP18: 45000 | DQ18: =(DI18*1000-DP18) -> 0 | DR18: =(DK18*DP18/1000) -> 41512.5 | DS18: =(DN18+42) -> 43297 | DT18: =(DR18*0.03) -> 1245.375 | DZ18: OC | EA18: DATA | ED18: PREÇO | EE18: CODIGO | EF18: DATA | EG18: DATA | EL18: DATA | EM18: VALOR DA
N19: =(O18) -> 58042.326 | P19: SERRAPLAST FEVEREIRO 2017 | AJ19: CUMBUCA 500 G - MA15 CRISTAL | AK19: 10 | AL19: VERBAL | AM19: 43710 | AN19: 20 | AO19: MIL | AP19: 290 | AR19: 43731 | AS19: 43729 | AT19: 3936 | AU19: 20000 | AV19: =(AU19-AN19*1000) -> 0 | AW19: =(AU19*AP19/1000) -> 5800 | AX19: =(AW19*0.05) -> 290 | BV19: OC | BW19: DATA | BZ19: PREÇO | CA19: CODIGO | CB19: DATA | CC19: DATA | CH19: VALOR DA | CK19: CLIENTE | CL19: PRODUTO | CM19: PEDIDO | CN19: DO | CO19: DO | CP19: QUANT | CQ19: UND | CR19: POR | CS19: DO | CT19: DE | CU19: DE | CV19: N F | CW19: QUANT | CX19: SALDO | CY19: VALOR | CZ19: COMISSÃO | DA19: COMISSÃO | DB19: OBSERVAÇÃO | DE19: CONJUNTO ENVASE MEL 200G | DF19: 135 | DH19: 43125 | DI19: 45 | DJ19: MIL | DK19: 922.5 | DM19: 43285 | DN19: 43291 | DO19: 13424 | DP19: 45000 | DQ19: =(DI19*1000-DP19) -> 0 | DR19: =(DK19*DP19/1000) -> 41512.5 | DS19: =(DN19+42) -> 43333 | DT19: =(DR19*0.03) -> 1245.375 | DW19: CLIENTE | DX19: PRODUTO | DY19: PEDIDO | DZ19: DO | EA19: DO | EB19: QUANT | EC19: UND | ED19: POR | EE19: DO | EF19: DE | EG19: DE | EH19: N F | EI19: QUANT | EJ19: SALDO | EK19: VALOR | EL19: COMISSÃO | EM19: COMISSÃO | EN19: OBSERVAÇÃO
B20: 2018 | S20: OC | T20: DATA | W20: PREÇO | X20: CODIGO | Y20: DATA | Z20: DATA | AE20: VALOR DA | AJ20: CUMBUCA 500 G - MA15 CRISTAL | AK20: 11 | AL20: VERBAL | AM20: 43781 | AN20: 100 | AO20: MIL | AP20: 330 | AR20: 43787 | AS20: 43787 | AT20: 3981 | AU20: 89000 | AV20: =(AU20-AN20*1000) -> -11000 | AW20: =(AU20*AP20/1000) -> 29370 | AX20: =(AW20*0.05) -> 1468.5 | BT20: PRODUTO | BU20: PEDIDO | BV20: DO | BW20: DO | BX20: QUANT | BY20: UND | BZ20: POR | CA20: DO | CB20: DE | CC20: DE | CD20: N F | CE20: QUANT | CF20: SALDO | CG20: VALOR | CH20: COMISSÃO | CI20: OBSERVAÇÃO | CN20: CLIENTE | CO20: PEDIDO | CR20: UND | CS20: CLIENTE | CT20: ENTREGA | CU20: FATURA | CZ20: 30 DD | DA20: R$ | DE20: CONJUNTO ENVASE MEL 200G | DF20: 136 | DH20: 43125 | DI20: 45 | DJ20: MIL | DK20: 922.5 | DM20: 43318 | DN20: 43313 | DO20: 13457 | DP20: 45000 | DQ20: =(DI20*1000-DP20) -> 0 | DR20: =(DK20*DP20/1000) -> 41512.5 | DS20: =(DN20+42) -> 43355 | DT20: =(DR20*0.03) -> 1245.375 | DZ20: CLIENTE | EA20: PEDIDO | ED20: UND | EE20: CLIENTE | EF20: ENTREGA | EG20: FATURA | EL20: 30 DD | EM20: R$
B21: REPRESENTADA | C21: JAN 12 | D21: FEV 01 | E21: MAR 02 | F21: ABR 03 | G21: MAI 04 | H21: JUN 05 | I21: JUL 06 | J21: AGO 07 | K21: SET 08 | L21: OUT 09 | M21: NOV 10 | N21: DEZ 11 | P21: CLIENTE | Q21: PRODUTO | R21: PEDIDO | S21: DO | T21: DO | U21: QUANT | V21: UND | W21: POR | X21: DO | Y21: DE | Z21: DE | AA21: N F | AB21: QUANT | AC21: SALDO | AD21: VALOR | AE21: COMISSÃO | AF21: OBSERVAÇÃO | AJ21: CUMBUCA 500 G - MA15 CRISTAL | AK21: 11 | AL21: VERBAL | AM21: 43781 | AN21: 11 | AO21: MIL | AP21: 330 | AR21: 43787 | AS21: 43793 | AT21: 3987 | AU21: 11000 | AV21: =(AU21-AN21*1000) -> 0 | AW21: =(AU21*AP21/1000) -> 3630 | AX21: =(AW21*0.05) -> 181.5 | BV21: CLIENTE | BW21: PEDIDO | BZ21: UND | CA21: CLIENTE | CB21: ENTREGA | CC21: FATURA | CH21: R$ | CK21: SUPERBOM | CL21: CONJUNTO ENVASE MEL 200G | CM21: 132 | CO21: 43125 | CP21: 45 | CQ21: MIL | CR21: 894.9 | CT21: 43179 | CU21: 43182 | CV21: 13255 | CW21: 45000 | CX21: =(CP21*1000-CW21) -> 0 | CY21: 40359.99 | CZ21: =(CU21+42) -> 43224 | DA21: =(CY21*0.03) -> 1210.7997 | DE21: CONJUNTO ENVASE MEL 200G | DF21: 137 | DH21: 43377 | DI21: 45 | DJ21: MIL | DK21: 984.5 | DM21: 43411 | DN21: 43427 | DO21: 13588 | DP21: 45000 | DQ21: =(DI21*1000-DP21) -> 0 | DR21: =(DK21*DP21/1000) -> 44302.5 | DS21: =(DN21+42) -> 43469 | DT21: =(DR21*0.03) -> 1329.075 | DW21: HORTA VITAE | DX21: ETIQUETA ADESIVA OVO CAIPIRA TG 20 UND | DY21: 1 | DZ21: E-MAIL | EA21: 44469 | EB21: 30 | EC21: MIL | ED21: 145.65 | EF21: 44480 | EG21: 44480 | EI21: 30000 | EJ21: =(EI21-EB21*1000) -> 0 | EK21: =(EI21*ED21/1000) -> 4369.5 | EM21: =(EK21*0.04) -> 174.78
S22: CLIENTE | T22: PEDIDO | W22: UND | X22: CLIENTE | Y22: ENTREGA | Z22: FATURA | AE22: R$ | AJ22: CUMBUCA 500 G - MA15 CRISTAL | AK22: 12 | AL22: VERBAL | AM22: 43781 | AN22: 11 | AO22: MIL | AP22: 330 | AR22: 43787 | AS22: 43793 | AT22: 3987 | AU22: 11000 | AV22: =(AU22-AN22*1000) -> 0 | AW22: =(AU22*AP22/1000) -> 3630 | AX22: =(AW22*0.05) -> 181.5 | BT22: FILME PVC ESTICAVEL 200 MM X 25 MICRA | BU22: 1 | BV22: VERBAL | BW22: 44365 | BX22: 1 | BY22: BOB | BZ22: 21.24 | CB22: 44377 | CE22: 1 | CF22: =(CE22-BX22) -> 0 | CG22: =(CE22*BZ22) -> 21.24 | CH22: =(CG22*0.05) -> 1.062 | DE22: CONJUNTO ENVASE MEL 200G | DF22: 138 | DH22: 43377 | DI22: 45 | DJ22: MIL | DK22: 984.5 | DM22: 43452 | DN22: 43490 | DO22: 13675 | DP22: 45000 | DQ22: =(DI22*1000-DP22) -> 0 | DR22: =(DK22*DP22/1000) -> 44302.5 | DS22: =(DN22+42) -> 43532 | DT22: =(DR22*0.03) -> 1329.075
B23: SERRAPLAST | C23: =(AE198) -> 6454.25 | D23: =(AE215) -> 6903.57 | E23: =(AE234) -> 8595.95 | F23: =(AE251) -> 5641.25 | G23: =(AE264) -> 2288 | H23: =(AE281) -> 6637.6 | I23: =(AE297) -> 5369.3 | J23: =(AE316) -> 7034.55 | K23: =(AE335) -> 7028.25 | L23: =(AE354) -> 4780.6 | M23: =(AE369) -> 6273 | N23: =(AE385) -> 5321.1875 | P23: CACO | Q23: CUMBUCA 500 G - MA 15 | R23: 6 | S23: VERBAL | T23: 42758 | U23: 15 | V23: MIL | W23: 335 | Y23: 42762 | Z23: 42758 | AA23: 1650 | AB23: 15000 | AC23: =(AB23-U23*1000) -> 0 | AD23: =(AB23*W23/1000) -> 5025 | AE23: =(AD23*0.05) -> 251.25 | AF23: PAGO | AJ23: CUMBUCA 500 G - MA15 CRISTAL | AK23: 13 | AL23: WHATSAPP | AM23: 43874 | AN23: 30 | AO23: MIL | AP23: 330 | AR23: 43881 | AS23: 43878 | AT23: 12628 | AU23: 30000 | AV23: =(AU23-AN23*1000) -> 0 | AW23: =(AU23*AP23/1000) -> 9900 | AX23: =(AW23*0.05) -> 495 | BT23: FILME PVC ESTICAVEL 500 MM X 25 MICRA | BU23: 2 | BV23: VERBAL | BW23: 44365 | BX23: 1 | BY23: BOB | BZ23: 21.24 | CB23: 44377 | CE23: 1 | CF23: =(CE23-BX23) -> 0 | CG23: =(CE23*BZ23) -> 21.24 | CH23: =(CG23*0.05) -> 1.062 | DE23: CONJUNTO ENVASE MEL 200G | DF23: 139 | DH23: 43496 | DI23: 45 | DJ23: MIL | DK23: 1018.96 | DM23: 43507 | DN23: 43514 | DO23: 13701 | DP23: 45000 | DQ23: =(DI23*1000-DP23) -> 0 | DR23: =(DK23*DP23/1000) -> 45853.2 | DS23: =(DN23+42) -> 43556 | DT23: =(DR23*0.03) -> 1375.596
P24: GO GREEN | Q24: CUMBUCA 500 G - MA 15 | R24: 3 | S24: VERBAL | T24: 42762 | U24: 20 | V24: MIL | W24: 315 | Y24: 42765 | Z24: 42765 | AA24: 9326 | AB24: 20000 | AC24: =(AB24-U24*1000) -> 0 | AD24: =(AB24*W24/1000) -> 6300 | AE24: =(AD24*0.05) -> 315 | AF24: PAGO | AJ24: CUMBUCA 500 G - MA15 CRISTAL | AK24: 14 | AL24: WHATSAPP | AM24: 43972 | AN24: 20 | AO24: MIL | AP24: 310 | AR24: 43976 | AS24: 43976 | AT24: 13174 | AU24: 20000 | AV24: =(AU24-AN24*1000) -> 0 | AW24: =(AU24*AP24/1000) -> 6200 | AX24: =(AW24*0.05) -> 310 | BT24: FILME PVC EST. 50 MM X 25 MICRA | BU24: 3 | BV24: 4500031322 | BW24: 44466 | BX24: 300 | BY24: BOB | BZ24: 17.32 | CB24: 44483 | CC24: 44483 | CD24: 63461 | CE24: 300.55 | CF24: =(CE24-BX24) -> 0.55 | CG24: =(CE24*BZ24) -> 5205.526 | CH24: =(CG24*0.025) -> 130.13815 | DE24: CONJUNTO ENVASE MEL 200G | DF24: 140 | DH24: 43496 | DI24: 45 | DJ24: MIL | DK24: 1018.96 | DM24: 43535 | DN24: 43621 | DO24: 13848 | DP24: 45000 | DQ24: =(DI24*1000-DP24) -> 0 | DR24: =(DK24*DP24/1000) -> 45853.2 | DS24: =(DN24+42) -> 43663 | DT24: =(DR24*0.03) -> 1375.596
B25: QUADRANTE | P25: GO GREEN | Q25: EMBALAGEM TOMATINHO - SRT 08 | R25: 4 | S25: VERBAL | T25: 42762 | U25: 30 | V25: MIL | W25: 154 | Y25: 42765 | Z25: 42765 | AA25: 9326 | AB25: 30000 | AC25: =(AB25-U25*1000) -> 0 | AD25: =(AB25*W25/1000) -> 4620 | AE25: =(AD25*0.05) -> 231 | AF25: PAGO | AJ25: CUMBUCA 500 G - MA15 CRISTAL | AK25: 15 | AL25: WHATSAPP | AM25: 43972 | AN25: 20 | AO25: MIL | AP25: 310 | AR25: 44011 | AS25: 44005 | AT25: 13316 | AU25: 20000 | AV25: =(AU25-AN25*1000) -> 0 | AW25: =(AU25*AP25/1000) -> 6200 | AX25: =(AW25*0.05) -> 310 | DE25: CONJUNTO ENVASE MEL 200G | DF25: 141 | DH25: 43496 | DI25: 45 | DJ25: MIL | DK25: 1018.96 | DM25: 43598 | DN25: 43602 | DO25: 13817 | DP25: 45000 | DQ25: =(DI25*1000-DP25) -> 0 | DR25: =(DK25*DP25/1000) -> 45853.2 | DS25: =(DN25+42) -> 43644 | DT25: =(DR25*0.03) -> 1375.596
P26: JOSE PAULO LAZZARI | Q26: EMB. OVO GALINHA 10 UND SRG - C10 | R26: 1 | S26: E-MAIL | T26: 42754 | U26: 1 | V26: MIL | W26: 430 | Y26: 42758 | Z26: 42766 | AA26: 9334 | AB26: 1000 | AC26: =(AB26-U26*1000) -> 0 | AD26: =(AB26*W26/1000) -> 430 | AE26: =(AD26*0.05) -> 21.5 | AF26: PAGO | AJ26: CUMBUCA 500 G - MA15 CRISTAL | AK26: 16 | AL26: WHATSAPP | AM26: 44034 | AN26: 30 | AO26: MIL | AP26: 310 | AR26: 44039 | AS26: 44037 | AT26: 13509 | AU26: 30000 | AV26: =(AU26-AN26*1000) -> 0 | AW26: =(AU26*AP26/1000) -> 9300 | AX26: =(AW26*0.05) -> 465 | DE26: CONJUNTO ENVASE MEL 200G | DF26: 142 | DH26: 43496 | DI26: 45 | DJ26: MIL | DK26: 1018.96 | DM26: 43626 | DN26: 43679 | DO26: 13923 | DP26: 45000 | DQ26: =(DI26*1000-DP26) -> 0 | DR26: =(DK26*DP26/1000) -> 45853.2 | DS26: =(DN26+42) -> 43721 | DT26: =(DR26*0.03) -> 1375.596
B27: CCS | C27: 1172.93 | D27: =(DA15) -> 1175.5135 | E27: =(DA28) -> 1210.7997 | F27: =(DA49) -> 1208.115 | G27: =(DA62) -> 0 | H27: =(DA75) -> 1245.375 | I27: =(DA68) -> 1245.375 | J27: =(DA90) -> 1245.375 | K27: 1245.38 | N27: =(DA136) -> 1329.075 | AJ27: CUMBUCA 500 G - MA15 CRISTAL | AK27: 17 | AL27: WHATSAPP | AM27: 44057 | AN27: 60 | AO27: MIL | AP27: 310 | AR27: 44067 | AS27: 44061 | AT27: 13686 | AU27: 60000 | AV27: =(AU27-AN27*1000) -> 0 | AW27: =(AU27*AP27/1000) -> 18600 | AX27: =(AW27*0.05) -> 930 | BA27: BRASIL SUL MAIO 2017 | DE27: CONJUNTO ENVASE MEL 200G | DF27: 143 | DH27: 43514 | DI27: 45 | DJ27: MIL | DK27: 1018.96 | DM27: 43564 | DN27: 43556 | DO27: 13759 | DP27: 45000 | DQ27: =(DI27*1000-DP27) -> 0 | DR27: =(DK27*DP27/1000) -> 45853.2 | DS27: =(DN27+42) -> 43598 | DT27: =(DR27*0.03) -> 1375.596
AD28: =SUM(AD23:AD27) -> 16375 | AE28: =(AD28*0.05) -> 818.75 | AJ28: CUMBUCA 500 G - MA15 CRISTAL | AK28: 18 | AL28: WHATSAPP | AM28: 44162 | AN28: 30 | AO28: MIL | AP28: 355 | AR28: 44172 | AS28: 44173 | AT28: 14477 | AU28: 30000 | AV28: =(AU28-AN28*1000) -> 0 | AW28: =(AU28*AP28/1000) -> 10650 | AX28: =(AW28*0.05) -> 532.5 | BD28: OC | BE28: DATA | BH28: PREÇO | BI28: CODIGO | BJ28: DATA | BK28: DATA | BP28: VALOR DA | BT28: COBREFLEX | BU28: ROBERTO R. LABLEUK 11 4707-0650 | BZ28: GIOVANI | CY28: =SUM(CY21:CY27) -> 40359.99 | DA28: =SUM(DA21:DA27) -> 1210.7997 | DE28: CONJUNTO ENVASE MEL 200G | DF28: 144 | DI28: 45 | DJ28: MIL | DK28: 1018.96 | DM28: 43854 | DN28: 43854 | DO28: 14150 | DP28: 45000 | DQ28: =(DI28*1000-DP28) -> 0 | DR28: =(DK28*DP28/1000) -> 45853.2 | DS28: =(DN28+42) -> 43896 | DT28: =(DR28*0.03) -> 1375.596 | DU28: PAGO | EK28: =SUM(EK21:EK27) -> 4369.5 | EM28: =SUM(EM21:EM27) -> 174.78
B29: BRASIL SUL | C29: =(BP123) -> 435 | D29: =(BP132) -> 439.41525 | E29: =(BP141) -> 438.2886 | F29: =(BP151) -> 606.35 | G29: =(BP159) -> 228.25 | H29: =(BP168) -> 255.25 | I29: =(BP177) -> 271.75942 | J29: =(BP187) -> 634.32764 | K29: =(BP199) -> 993.4542 | L29: =(BP208) -> 485.97156 | M29: =(BP218) -> 677.45808 | N29: =(BP230) -> 1982.3908 | AJ29: CUMBUCA 500 G - MA15 CRISTAL | AK29: 19 | AL29: WHATSAPP | AM29: 44215 | AN29: 20 | AO29: MIL | AP29: 390 | AR29: 44217 | AS29: 44225 | AT29: 14820 | AU29: 20000 | AV29: =(AU29-AN29*1000) -> 0 | AW29: =(AU29*AP29/1000) -> 7800 | AX29: =(AW29*0.05) -> 390 | BA29: CLIENTE | BB29: PRODUTO | BC29: PEDIDO | BD29: DO | BE29: DO | BF29: QUANT | BG29: UND | BH29: POR | BI29: DO | BJ29: DE | BK29: DE | BL29: N F | BM29: QUANT | BN29: SALDO | BO29: VALOR | BP29: COMISSÃO | BQ29: OBSERVAÇÃO | BV29: OC | BW29: DATA | BZ29: PREÇO | CA29: CODIGO | CB29: DATA | CC29: DATA | CH29: VALOR DA | DE29: CONJUNTO ENVASE MEL 200G | DF29: 144 | DG29: VERBAL | DH29: 43867 | DI29: 45 | DJ29: MIL | DK29: 1111.57 | DM29: 43885 | DN29: 43880 | DO29: 14181 | DP29: 45000 | DQ29: =(DI29*1000-DP29) -> 0 | DR29: =(DK29*DP29/1000) -> 50020.65 | DS29: =(DN29+42) -> 43922 | DT29: =(DR29*0.03) -> 1500.6195 | DU29: PAGO
P30: SERRAPLAST MARÇO 2017 | AJ30: CUMBUCA 500 G - MA15 CRISTAL | AK30: 20 | AL30: WHATSAPP | AM30: 44264 | AN30: 30 | AO30: MIL | AP30: 350 | AR30: 44267 | AS30: 44265 | AT30: 15109 | AU30: 30000 | AV30: =(AU30-AN30*1000) -> 0 | AW30: =(AU30*AP30/1000) -> 10500 | AX30: =(AW30*0.05) -> 525 | BD30: CLIENTE | BE30: PEDIDO | BH30: UND | BI30: CLIENTE | BJ30: ENTREGA | BK30: FATURA | BP30: R$ | BT30: PRODUTO | BU30: PEDIDO | BV30: DO | BW30: DO | BX30: QUANT | BY30: UND | BZ30: POR | CA30: DO | CB30: DE | CC30: DE | CD30: N F | CE30: QUANT | CF30: SALDO | CG30: VALOR | CH30: COMISSÃO | CI30: OBSERVAÇÃO | CK30: CCS MAIO 2018 | DE30: CONJUNTO ENVASE MEL 200G | DF30: 145 | DG30: VERBAL | DH30: 43867 | DI30: 45 | DJ30: MIL | DK30: 1111.57 | DM30: 43914 | DN30: 43929 | DO30: 14265 | DP30: 45000 | DQ30: =(DI30*1000-DP30) -> 0 | DR30: =(DK30*DP30/1000) -> 50020.65 | DS30: =(DN30+42) -> 43971 | DT30: =(DR30*0.03) -> 1500.6195 | DU30: PAGO | DW30: EDIPRINT DEZEMBRO 2021
S31: OC | T31: DATA | W31: PREÇO | X31: CODIGO | Y31: DATA | Z31: DATA | AE31: VALOR DA | AJ31: CUMBUCA 500 G - MA15 CRISTAL | AK31: 21 | AL31: WHATSAPP | AM31: 44312 | AN31: 40 | AO31: MIL | AP31: 335 | AR31: 44312 | AS31: 44313 | AT31: 15380 | AU31: 30000 | AV31: =(AU31-AN31*1000) -> -10000 | AW31: =(AU31*AP31/1000) -> 10050 | AX31: =(AW31*0.05) -> 502.5 | BA31: METALFLEX | BB31: FILME PVC EST. 60 MM X 40 MICRA | BC31: 1 | BD31: e-mail | BE31: 42822 | BF31: 1000 | BG31: KG | BH31: 9.7 | BJ31: 42829 | BK31: 42829 | BL31: 46790 | BM31: 1010.66 | BN31: =(BM31-BF31) -> 10.66 | BO31: 8792.74 | BP31: =(BO31*0.05) -> 439.637 | BQ31: PAGO | BV31: CLIENTE | BW31: PEDIDO | BZ31: UND | CA31: CLIENTE | CB31: ENTREGA | CC31: FATURA | CH31: R$ | CN31: OC | CO31: DATA | CR31: PREÇO | CS31: CODIGO | CT31: DATA | CU31: DATA | CZ31: DATA | DA31: VALOR DA | DE31: CONJUNTO ENVASE MEL 200G | DF31: 146 | DG31: VERBAL | DH31: 43937 | DI31: 45 | DJ31: MIL | DK31: 1111.57 | DM31: 43969 | DN31: 43966 | DO31: 14326 | DP31: 45100 | DQ31: =(DI31*1000-DP31) -> -100 | DR31: =(DK31*DP31/1000) -> 50131.807 | DS31: =(DN31+42) -> 44008 | DT31: =(DR31*0.03) -> 1503.9542 | DU31: PAGO | DZ31: OC | EA31: DATA | ED31: PREÇO | EE31: CODIGO | EF31: DATA | EG31: DATA | EL31: DATA | EM31: VALOR DA
